Workbook

Sheet Petunjuk
A1: Skenario Uji Aplikasi EGZY
A3: Urutan pengujian mengikuti alur data: data master, lalu transaksi, lalu laporan. Kerjakan dari atas ke bawah di lembar Skenario Uji.
A4: Kolom yang Anda isi berwarna kuning: Hasil aktual, Status, Catatan, Tanggal uji, Penguji.
A5: Status dipilih dari daftar: Lulus, Gagal, Diblokir, Belum diuji. Diblokir berarti tidak bisa diuji karena skenario prasyaratnya gagal.
A6: Lembar Ringkasan menghitung otomatis dari kolom Status.
A7: Baris TC-038 (menu Records) sudah diisi sebagai contoh cara mengisi, berdasarkan error 500 yang terlihat di screenshot.
A8: Data uji hanyalah saran; ganti sesuai kebutuhan. Hasil yang diharapkan disusun dari tampilan form di screenshot, jadi sesuaikan bila perilaku aplikasi yang benar ternyata berbeda.
A9: Lembar Temuan Awal berisi hal-hal yang sudah terlihat di screenshot sebelum pengujian dimulai.
A10: Lembar Rekonsiliasi WP berisi 11 skenario untuk dashboard Bapenda, satu per peran WP contoh; diisi dengan cara yang sama dan dihitung terpisah di Ringkasan.
A11: Lembar Akun Uji memuat akun dan kata sandi lingkungan demo; kolom Akun uji di tiap skenario menunjukkan akun yang dipakai. TC-051 sampai TC-053 menguji isolasi antar-tenant.
A13: Pembaruan 9 Okt 2026 (pengembang): kolom "Tindak lanjut pengembang" dan "Status perbaikan" ditambahkan di lembar Skenario Uji, Rekonsiliasi WP, dan Perbaikan desain; kolom Status perbaikan di Temuan Awal diisi. Kolom isian penguji tidak diubah. Baris "Diperbaiki – uji ulang" perlu diuji ulang setelah rilis 9 Okt 2026 di-deploy ke server.

Sheet Akun Uji
A1: Email | B1: Peran | C1: Kata sandi | D1: Dipakai untuk
A2: bapenda@egzy.test | B2: Bapenda: semua WP, temuan, tagihan, kelola tenant | C2: Demo#2026 | D2: Lembar Rekonsiliasi WP (RK-01 sampai RK-11); Pengawasan PBJT (TC-046, TC-047)
A3: melati@egzy.test | B3: Admin tenant Melati | C3: Demo#2026 | D3: Alur hotel dan modul umum; uji isolasi tenant (TC-051, TC-052)
A4: serena@egzy.test | B4: Admin tenant Serena | C4: Demo#2026 | D4: Sisi WP dari kasus kurang lapor (RK-04)
A5: villa@egzy.test | B5: Admin tenant Villa Asri | C5: Demo#2026 | D5: Tenant baru: kamar ada, belum ada tagihan (RK-09)
A6: cempaka@egzy.test | B6: Admin tenant Cempaka | C6: Demo#2026 | D6: Sisi WP dari kasus telat bayar (RK-08)
A7: bahari@egzy.test | B7: Admin tenant Bahari (restoran POS) | C7: Demo#2026 | D7: Alur restoran, stok, dan uji role kasir (TC-025 sampai TC-036, TC-048)
A8: nirwana@egzy.test | B8: Admin tenant Nirwana | C8: Demo#2026 | D8: WP patuh dan pembayaran VA BNI (RK-03, RK-11)
A9: tamu1.wp001@egzy.test dst. | B9: Tamu website | C9: Demo#2026 | D9: Booking dari website (TC-053)
A11: Sumber: pesan pengembang. Kata sandi sama untuk semua akun dan hanya berlaku di lingkungan demo. Kolom Dipakai untuk adalah saran pembagian, bukan ketentuan dari pengembang.

Sheet Ringkasan
A1: Modul | B1: Jumlah skenario | C1: Lulus | D1: Gagal | E1: Diblokir | F1: Belum diuji | G1: % selesai
A2: Pengaturan dasar | B2: =COUNTIF('Skenario Uji'!$B$2:$B$54,A2) -> 4 | C2: =COUNTIFS('Skenario Uji'!$B$2:$B$54,$A2,'Skenario Uji'!$I$2:$I$54,"Lulus") -> 4 | D2: =COUNTIFS('Skenario Uji'!$B$2:$B$54,$A2,'Skenario Uji'!$I$2:$I$54,"Gagal") -> 0 | E2: =COUNTIFS('Skenario Uji'!$B$2:$B$54,$A2,'Skenario Uji'!$I$2:$I$54,"Diblokir") -> 0 | F2: =COUNTIFS('Skenario Uji'!$B$2:$B$54,$A2,'Skenario Uji'!$I$2:$I$54,"Belum diuji") -> 0 | G2: =IF(B2=0,0,(B2-F2)/B2) -> 1
A3: Human Resource | B3: =COUNTIF('Skenario Uji'!$B$2:$B$54,A3) -> 7 | C3: =COUNTIFS('Skenario Uji'!$B$2:$B$54,$A3,'Skenario Uji'!$I$2:$I$54,"Lulus") -> 7 | D3: =COUNTIFS('Skenario Uji'!$B$2:$B$54,$A3,'Skenario Uji'!$I$2:$I$54,"Gagal") -> 0 | E3: =COUNTIFS('Skenario Uji'!$B$2:$B$54,$A3,'Skenario Uji'!$I$2:$I$54,"Diblokir") -> 0 | F3: =COUNTIFS('Skenario Uji'!$B$2:$B$54,$A3,'Skenario Uji'!$I$2:$I$54,"Belum diuji") -> 0 | G3: =IF(B3=0,0,(B3-F3)/B3) -> 1
A4: Duty Roster | B4: =COUNTIF('Skenario Uji'!$B$2:$B$54,A4) -> 1 | C4: =COUNTIFS('Skenario Uji'!$B$2:$B$54,$A4,'Skenario Uji'!$I$2:$I$54,"Lulus") -> 1 | D4: =COUNTIFS('Skenario Uji'!$B$2:$B$54,$A4,'Skenario Uji'!$I$2:$I$54,"Gagal") -> 0 | E4: =COUNTIFS('Skenario Uji'!$B$2:$B$54,$A4,'Skenario Uji'!$I$2:$I$54,"Diblokir") -> 0 | F4: =COUNTIFS('Skenario Uji'!$B$2:$B$54,$A4,'Skenario Uji'!$I$2:$I$54,"Belum diuji") -> 0 | G4: =IF(B4=0,0,(B4-F4)/B4) -> 1
A5: Kamar | B5: =COUNTIF('Skenario Uji'!$B$2:$B$54,A5) -> 6 | C5: =COUNTIFS('Skenario Uji'!$B$2:$B$54,$A5,'Skenario Uji'!$I$2:$I$54,"Lulus") -> 6 | D5: =COUNTIFS('Skenario Uji'!$B$2:$B$54,$A5,'Skenario Uji'!$I$2:$I$54,"Gagal") -> 0 | E5: =COUNTIFS('Skenario Uji'!$B$2:$B$54,$A5,'Skenario Uji'!$I$2:$I$54,"Diblokir") -> 0 | F5: =COUNTIFS('Skenario Uji'!$B$2:$B$54,$A5,'Skenario Uji'!$I$2:$I$54,"Belum diuji") -> 0 | G5: =IF(B5=0,0,(B5-F5)/B5) -> 1
A6: Reservasi | B6: =COUNTIF('Skenario Uji'!$B$2:$B$54,A6) -> 6 | C6: =COUNTIFS('Skenario Uji'!$B$2:$B$54,$A6,'Skenario Uji'!$I$2:$I$54,"Lulus") -> 2 | D6: =COUNTIFS('Skenario Uji'!$B$2:$B$54,$A6,'Skenario Uji'!$I$2:$I$54,"Gagal") -> 4 | E6: =COUNTIFS('Skenario Uji'!$B$2:$B$54,$A6,'Skenario Uji'!$I$2:$I$54,"Diblokir") -> 0 | F6: =COUNTIFS('Skenario Uji'!$B$2:$B$54,$A6,'Skenario Uji'!$I$2:$I$54,"Belum diuji") -> 0 | G6: =IF(B6=0,0,(B6-F6)/B6) -> 1
A7: Restoran | B7: =COUNTIF('Skenario Uji'!$B$2:$B$54,A7) -> 8 | C7: =COUNTIFS('Skenario Uji'!$B$2:$B$54,$A7,'Skenario Uji'!$I$2:$I$54,"Lulus") -> 6 | D7: =COUNTIFS('Skenario Uji'!$B$2:$B$54,$A7,'Skenario Uji'!$I$2:$I$54,"Gagal") -> 2 | E7: =COUNTIFS('Skenario Uji'!$B$2:$B$54,$A7,'Skenario Uji'!$I$2:$I$54,"Diblokir") -> 0 | F7: =COUNTIFS('Skenario Uji'!$B$2:$B$54,$A7,'Skenario Uji'!$I$2:$I$54,"Belum diuji") -> 0 | G7: =IF(B7=0,0,(B7-F7)/B7) -> 1
A8: Stok dan pembelian | B8: =COUNTIF('Skenario Uji'!$B$2:$B$54,A8) -> 4 | C8: =COUNTIFS('Skenario Uji'!$B$2:$B$54,$A8,'Skenario Uji'!$I$2:$I$54,"Lulus") -> 3 | D8: =COUNTIFS('Skenario Uji'!$B$2:$B$54,$A8,'Skenario Uji'!$I$2:$I$54,"Gagal") -> 1 | E8: =COUNTIFS('Skenario Uji'!$B$2:$B$54,$A8,'Skenario Uji'!$I$2:$I$54,"Diblokir") -> 0 | F8: =COUNTIFS('Skenario Uji'!$B$2:$B$54,$A8,'Skenario Uji'!$I$2:$I$54,"Belum diuji") -> 0 | G8: =IF(B8=0,0,(B8-F8)/B8) -> 1
A9: House Keeping | B9: =COUNTIF('Skenario Uji'!$B$2:$B$54,A9) -> 3 | C9: =COUNTIFS('Skenario Uji'!$B$2:$B$54,$A9,'Skenario Uji'!$I$2:$I$54,"Lulus") -> 1 | D9: =COUNTIFS('Skenario Uji'!$B$2:$B$54,$A9,'Skenario Uji'!$I$2:$I$54,"Gagal") -> 2 | E9: =COUNTIFS('Skenario Uji'!$B$2:$B$54,$A9,'Skenario Uji'!$I$2:$I$54,"Diblokir") -> 0 | F9: =COUNTIFS('Skenario Uji'!$B$2:$B$54,$A9,'Skenario Uji'!$I$2:$I$54,"Belum diuji") -> 0 | G9: =IF(B9=0,0,(B9-F9)/B9) -> 1
A10: Transport | B10: =COUNTIF('Skenario Uji'!$B$2:$B$54,A10) -> 1 | C10: =COUNTIFS('Skenario Uji'!$B$2:$B$54,$A10,'Skenario Uji'!$I$2:$I$54,"Lulus") -> 1 | D10: =COUNTIFS('Skenario Uji'!$B$2:$B$54,$A10,'Skenario Uji'!$I$2:$I$54,"Gagal") -> 0 | E10: =COUNTIFS('Skenario Uji'!$B$2:$B$54,$A10,'Skenario Uji'!$I$2:$I$54,"Diblokir") -> 0 | F10: =COUNTIFS('Skenario Uji'!$B$2:$B$54,$A10,'Skenario Uji'!$I$2:$I$54,"Belum diuji") -> 0 | G10: =IF(B10=0,0,(B10-F10)/B10) -> 1
A11: Car Parking | B11: =COUNTIF('Skenario Uji'!$B$2:$B$54,A11) -> 2 | C11: =COUNTIFS('Skenario Uji'!$B$2:$B$54,$A11,'Skenario Uji'!$I$2:$I$54,"Lulus") -> 0 | D11: =COUNTIFS('Skenario Uji'!$B$2:$B$54,$A11,'Skenario Uji'!$I$2:$I$54,"Gagal") -> 2 | E11: =COUNTIFS('Skenario Uji'!$B$2:$B$54,$A11,'Skenario Uji'!$I$2:$I$54,"Diblokir") -> 0 | F11: =COUNTIFS('Skenario Uji'!$B$2:$B$54,$A11,'Skenario Uji'!$I$2:$I$54,"Belum diuji") -> 0 | G11: =IF(B11=0,0,(B11-F11)/B11) -> 1
A12: Hall Room | B12: =COUNTIF('Skenario Uji'!$B$2:$B$54,A12) -> 1 | C12: =COUNTIFS('Skenario Uji'!$B$2:$B$54,$A12,'Skenario Uji'!$I$2:$I$54,"Lulus") -> 1 | D12: =COUNTIFS('Skenario Uji'!$B$2:$B$54,$A12,'Skenario Uji'!$I$2:$I$54,"Gagal") -> 0 | E12: =COUNTIFS('Skenario Uji'!$B$2:$B$54,$A12,'Skenario Uji'!$I$2:$I$54,"Diblokir") -> 0 | F12: =COUNTIFS('Skenario Uji'!$B$2:$B$54,$A12,'Skenario Uji'!$I$2:$I$54,"Belum diuji") -> 0 | G12: =IF(B12=0,0,(B12-F12)/B12) -> 1
A13: Laporan dan akun | B13: =COUNTIF('Skenario Uji'!$B$2:$B$54,A13) -> 2 | C13: =COUNTIFS('Skenario Uji'!$B$2:$B$54,$A13,'Skenario Uji'!$I$2:$I$54,"Lulus") -> 1 | D13: =COUNTIFS('Skenario Uji'!$B$2:$B$54,$A13,'Skenario Uji'!$I$2:$I$54,"Gagal") -> 0 | E13: =COUNTIFS('Skenario Uji'!$B$2:$B$54,$A13,'Skenario Uji'!$I$2:$I$54,"Diblokir") -> 0 | F13: =COUNTIFS('Skenario Uji'!$B$2:$B$54,$A13,'Skenario Uji'!$I$2:$I$54,"Belum diuji") -> 1 | G13: =IF(B13=0,0,(B13-F13)/B13) -> 0.5
... A16: Tampilan | B16: =COUNTIF('Skenario Uji'!$B$2:$B$54,A16) -> 2 | C16: =COUNTIFS('Skenario Uji'!$B$2:$B$54,$A16,'Skenario Uji'!$I$2:$I$54,"Lulus") -> 2 | D16: =COUNTIFS('Skenario Uji'!$B$2:$B$54,$A16,'Skenario Uji'!$I$2:$I$54,"Gagal") -> 0 | E16: =COUNTIFS('Skenario Uji'!$B$2:$B$54,$A16,'Skenario Uji'!$I$2:$I$54,"Diblokir") -> 0 | F16: =COUNTIFS('Skenario Uji'!$B$2:$B$54,$A16,'Skenario Uji'!$I$2:$I$54,"Belum diuji") -> 0 | G16: =IF(B16=0,0,(B16-F16)/B16) -> 1
A17: Total | B17: =SUM(B2:B16) -> 53 | C17: =SUM(C2:C16) -> 41 | D17: =SUM(D2:D16) -> 11 | E17: =SUM(E2:E16) -> 0 | F17: =SUM(F2:F16) -> 1 | G17: =IF(B17=0,0,(B17-F17)/B17) -> 0.98113208
A19: Rekonsiliasi WP | B19: =COUNTA('Rekonsiliasi WP'!$A$2:$A$12) -> 11 | C19: =COUNTIF('Rekonsiliasi WP'!$H$2:$H$12,"Lulus") -> 7 | D19: =COUNTIF('Rekonsiliasi WP'!$H$2:$H$12,"Gagal") -> 4 | E19: =COUNTIF('Rekonsiliasi WP'!$H$2:$H$12,"Diblokir") -> 0 | F19: =COUNTIF('Rekonsiliasi WP'!$H$2:$H$12,"Belum diuji") -> 0 | G19: =IF(B19=0,0,(B19-F19)/B19) -> 1
A21: Status perbaikan (pengembang) | B21: Skenario Uji | C21: Rekonsiliasi WP
A22: Diperbaiki – uji ulang | B22: =COUNTIF('Skenario Uji'!$O$2:$O$54,$A22) -> 25 | C22: =COUNTIF('Rekonsiliasi WP'!$N$2:$N$12,$A22) -> 7
A23: Perlu ubah skenario | B23: =COUNTIF('Skenario Uji'!$O$2:$O$54,$A23) -> 1 | C23: =COUNTIF('Rekonsiliasi WP'!$N$2:$N$12,$A23) -> 0
A24: Tidak ada perubahan | B24: =COUNTIF('Skenario Uji'!$O$2:$O$54,$A24) -> 27 | C24: =COUNTIF('Rekonsiliasi WP'!$N$2:$N$12,$A24) -> 4
A25: Total | B25: =SUM(B22:B24) -> 53 | C25: =SUM(C22:C24) -> 11

Sheet Skenario Uji
A1: ID | B1: Modul | C1: Skenario | D1: Prasyarat | E1: Langkah | F1: Data uji | G1: Hasil yang diharapkan | H1: Hasil aktual | I1: Status | J1: Catatan | K1: Tanggal uji | L1: Penguji | M1: Akun uji | N1: Tindak lanjut pengembang (9 Okt 2026) | O1: Status perbaikan
A2: TC-001 | B2: Pengaturan dasar | C2: Tambah payment method | D2: Login sebagai Administrator | E2: Payment Setting > Payment method list > tambah data > simpan | F2: Nama: Tunai | G2: Data tampil di daftar dan bisa dipilih saat pembayaran | H2: Belum ada button untuk tambah Payment, edit payment bisa, active/inactive payment methode bisa | I2: Lulus | J2: Tambahkan button add payment | K2: 46302 | L2: FERI | M2: melati@egzy.test | N2: Tombol "Add New" ditambahkan di Payment method list (modal tambah sudah ada, tombolnya hilang). Simpan gagal validasi tidak lagi membuka halaman rusak. Berlaku di server setelah rilis 9 Okt 2026 di-deploy. | O2: Diperbaiki – uji ulang
A3: TC-002 | B3: Pengaturan dasar | C3: Tambah pajak | D3: - | E3: Tax Management > Tax list > Add New > isi > Add | F3: Tax Name: PBJT Hotel; Rate: 10; Reg No: 001; Is Active: ya | G3: Pajak tampil di Tax list dengan status aktif | H3: Sudah sesuai | I3: Lulus | K3: 46302 | L3: FERI | M3: melati@egzy.test | N3: Tax Management kini MENOLAK entri pajak daerah (PBJT/PB1/pajak hotel/restoran): PBJT dihitung otomatis oleh sistem dengan tarif ketetapan Pemda (10%). Ganti data uji dengan komponen non-PBJT, mis. "Service Charge 5%"; tambahkan langkah: coba "PBJT Hotel" -> harus ditolak. Berlaku di server setelah rilis 9 Okt 2026 di-deploy. | O3: Perlu ubah skenario
A4: TC-003 | B4: Pengaturan dasar | C4: Tambah counter | D4: - | E4: Day Closing > Counterlist > isi Counter No > Add Counter | F4: Counter No: 2 | G4: Counter 2 tampil di daftar dan muncul di pop-up Start Cash Register | H4: Sudah sesuai | I4: Lulus | K4: 46302 | L4: FERI | M4: melati@egzy.test | O4: Tidak ada perubahan
A5: TC-004 | B5: Pengaturan dasar | C5: Validasi kolom wajib | D5: - | E5: Buka form Tax list > Add New > klik Add tanpa mengisi | F5: Semua kolom kosong | G5: Muncul pesan kolom wajib; data tidak tersimpan | H5: Sudah sesuai | I5: Lulus | K5: 46302 | L5: FERI | M5: melati@egzy.test | O5: Tidak ada perubahan
A6: TC-005 | B6: Human Resource | C6: Tambah department dan division | D6: - | E6: Department > Department list > tambah; lalu Add division | F6: Department: Front Office; Division: Resepsionis | G6: Keduanya tampil di daftar; division terhubung ke department | H6: Sudah sesuai | I6: Lulus | K6: 46302 | L6: FERI | M6: melati@egzy.test | O6: Tidak ada perubahan
A7: TC-006 | B7: Human Resource | C7: Tambah position | D7: - | E7: Employee > Position > tambah | F7: Position: Resepsionis | G7: Position tampil dan bisa dipilih di Add employee | H7: Sudah sesuai | I7: Lulus | K7: 46302 | L7: FERI | M7: melati@egzy.test | O7: Tidak ada perubahan
A8: TC-007 | B8: Human Resource | C8: Tambah pegawai | D8: Department, division, position sudah ada | E8: Employee > Add employee > isi > simpan | F8: Nama: Budi Santoso; Position: Resepsionis | G8: Pegawai tampil di Manage employee | H8: Sudah sesuai | I8: Lulus | K8: 46303 | L8: FERI | M8: melati@egzy.test | N8: Label SSN diganti NIK (maks. 16 digit). Datepicker tanggal di form pegawai tidak lagi "Invalid date" (lihat TC-029). Berlaku di server setelah rilis 9 Okt 2026 di-deploy. | O8: Diperbaiki – uji ulang
A9: TC-008 | B9: Human Resource | C9: Catat kehadiran | D9: Pegawai sudah ada | E9: Attendance > Attendance > pilih pegawai > isi jam masuk/keluar | F9: Budi Santoso; 08:00 - 16:00 | G9: Kehadiran tersimpan dan muncul di Attendance reports | H9: Sudah sesuai | I9: Lulus | K9: 46303 | L9: FERI | M9: melati@egzy.test | O9: Tidak ada perubahan
A10: TC-009 | B10: Human Resource | C10: Pengajuan cuti | D10: Leave type sudah ada | E10: Leave > Add leave type; lalu Leave application > isi > simpan | F10: Tipe: Cuti Tahunan; 2 hari | G10: Pengajuan tampil di daftar dengan jumlah hari benar | H10: Sudah sesuai | I10: Lulus | K10: 46303 | L10: FERI | M10: melati@egzy.test | O10: Tidak ada perubahan
A11: TC-010 | B11: Human Resource | C11: Pinjaman pegawai | D11: Pegawai sudah ada | E11: Loan > Grant loan > isi; lalu Loan installment | F11: Pinjaman: 1.000.000; cicilan 2x | G11: Pinjaman dan cicilan tampil; Loan report menunjukkan sisa yang benar | H11: Sudah sesuai | I11: Lulus | K11: 46303 | L11: FERI | M11: melati@egzy.test | O11: Tidak ada perubahan
A12: TC-011 | B12: Human Resource | C12: Generate gaji | D12: Salary type dan salary setup sudah ada | E12: Payroll > Salary type setup > Salary setup > Salary generate | F12: Gaji pokok: 4.000.000; periode bulan berjalan | G12: Gaji ter-generate; potongan pinjaman ikut terhitung | H12: Sudah sesuai | I12: Lulus | K12: 46303 | L12: FERI | M12: melati@egzy.test | O12: Tidak ada perubahan
A13: TC-012 | B13: Duty Roster | C13: Buat shift dan roster | D13: Pegawai sudah ada | E13: Shift list > Add Shift; Roster list > Create Roster; Roster assign | F13: Shift Pagi 07:00-15:00; roster 7 hari | G13: Pegawai tampil di Assigned Employee List dan Attendance dashboard | H13: Sudah sesuai | I13: Lulus | K13: 46303 | L13: FERI | M13: melati@egzy.test | O13: Tidak ada perubahan
A14: TC-013 | B14: Kamar | C14: Tambah fasilitas dan ukuran kamar | D14: - | E14: Room Facilities > Facility list, Facility details list, Room size list > tambah | F14: Fasilitas: AC; Ukuran: 24 m2 | G14: Data tampil dan bisa dipilih di form Room list | H14: Gambar kamar tidak muncul | I14: Lulus | K14: 46303 | L14: FERI | M14: melati@egzy.test | N14: Ronde 2 (9 Okt): Gambar kamar tidak tampil karena folder upload gambar kamar (room_setting) tidak bisa ditulis web server di VM. Skrip deploy kini memberi izin tulis ke SEMUA folder upload modul (kamar, fasilitas, hall, menu, pegawai). Unggah ulang gambar kamar setelah deploy. Berlaku setelah rilis berikutnya di-deploy (sertakan migrasi 011–012) dan cache Cloudflare di-purge. | O14: Diperbaiki – uji ulang
A15: TC-014 | B15: Kamar | C15: Tambah tipe kamar | D15: Bed list dan room size sudah ada | E15: Room Setting > Room list > Add New > isi > Add | F15: Room Type: Deluxe; Capacity: 2; Rate: 500.000; Bed: King Bed | G15: Tipe kamar tampil di Room list dengan tarif benar | H15: Sudah sesuai | I15: Lulus | K15: 46303 | L15: FERI | M15: melati@egzy.test | O15: Tidak ada perubahan
A16: TC-015 | B16: Kamar | C16: Atur lantai dan nomor kamar | D16: Tipe kamar sudah ada | E16: Room Setting > Floor plan list > Add Floor > Assign Floor | F16: Lantai 1; Start Room No: 101; No of Room: 5 | G16: Kamar 101-105 terbentuk dan tampil di Room status | H16: Sudah sesuai | I16: Lulus | K16: 46303 | L16: FERI | M16: melati@egzy.test | O16: Tidak ada perubahan
A17: TC-016 | B17: Kamar | C17: Booking type dan booking source | D17: - | E17: Room Setting > Booking type list > Add New; Booking source > Add New | F17: Type: Online; Source: Traveloka; Commission: 10 | G17: Keduanya tampil; source terhubung ke type | H17: Sudah sesuai | I17: Lulus | K17: 46303 | L17: FERI | M17: melati@egzy.test | O17: Tidak ada perubahan
A18: TC-017 | B18: Kamar | C18: Promocode | D18: Tipe kamar sudah ada | E18: Room Setting > Promocode > New Promocode > isi > Add | F18: Deluxe; kode HEMAT10; Discount: 10; periode 7 hari | G18: Promocode tampil aktif dan memotong harga saat booking | H18: Sudah sesuai | I18: Lulus | K18: 46303 | L18: FERI | M18: melati@egzy.test | O18: Tidak ada perubahan
A19: TC-018 | B19: Kamar | C19: Room QR list | D19: Kamar sudah ada | E19: House Keeping > Room QR list | F19: - | G19: QR tampil untuk setiap kamar (saat ini halaman kosong) | H19: Sudah sesuai | I19: Lulus | J19: https://drive.google.com/file/d/1m4NQ6H8itiwmXEv0_IkvlGX0VaXEPOO3/view?usp=drive_link | K19: 46303 | L19: FERI | M19: melati@egzy.test | N19: Penyebab: QR memakai layanan Google Chart yang sudah dimatikan Google. QR kini dibuat di server (library lokal); gambar tampil untuk semua kamar, juga di cetakan. Berlaku di server setelah rilis 9 Okt 2026 di-deploy. | O19: Diperbaiki – uji ulang
A20: TC-019 | B20: Reservasi | C20: Tambah customer | D20: - | E20: Customer > Customer list > tambah | F20: Nama: Siti Aminah; HP: 0812xxxxxxx | G20: Customer tampil di Customer list | H20: Sudah sesuai | I20: Lulus | J20: https://drive.google.com/file/d/1BupoCFgw8RShkFJwKS16niLb9vdaazU-/view?usp=sharing | K20: 46303 | L20: FERI | M20: melati@egzy.test | N20: Penyebab: cek "nomor HP harus unik" berjalan saat form baru dibuka (HP kosong cocok dengan customer lama tanpa HP) sehingga form ditolak. Kini hanya dicek bila HP diisi. Berlaku di server setelah rilis 9 Okt 2026 di-deploy. | O20: Diperbaiki – uji ulang
A21: TC-020 | B21: Reservasi | C21: Buat booking kamar | D21: Customer dan kamar sudah ada | E21: Room Reservation > Booking list > tambah booking > simpan | F21: Siti Aminah; Deluxe 101; 2 malam | G21: Booking tampil; total = 2 x tarif + pajak; kamar 101 berstatus terpesan | H21: setelah isi form kemudian disimpan data tidak muncul di tabel (DATA MASIH BELUM MUNCUL DI TABEL SETELAH DI ADD BOOKING) | I21: Gagal | J21: https://drive.google.com/file/d/1wVlvJMaypcEjSD-nRL3DRFdfSxpuGCrc/view?usp=drive_link | M21: melati@egzy.test | N21: Ronde 2 (9 Okt): Tahun buku kini dibuat otomatis bila tidak ada yang mencakup hari ini (dulu migrasi hanya mengisi tabel yang kosong total). Bila masih gagal setelah deploy, jalankan "sudo -u www-data php pbjt_diagnosa.php" di server dan kirim hasilnya; skrip memeriksa migrasi, tahun buku, dan 5 booking terakhir per tenant. Berlaku setelah rilis berikutnya di-deploy (sertakan migrasi 011–012) dan cache Cloudflare di-purge. | O21: Diperbaiki – uji ulang
A22: TC-021 | B22: Reservasi | C22: Check in | D22: Booking sudah ada | E22: Room Reservation > Check in > pilih booking > proses | F22: Booking Siti Aminah | G22: Status menjadi check in; tampil di Guest list | H22: data tidak muncul di tabel | I22: Gagal | J22: https://drive.google.com/file/d/1wVlvJMaypcEjSD-nRL3DRFdfSxpuGCrc/view?usp=drive_link | M22: melati@egzy.test | N22: Terblokir penyebab yang sama dengan TC-020 (booking tak bisa dibuat). Pencarian di Check-in list juga diperbaiki (dulu selalu error). Berlaku di server setelah rilis 9 Okt 2026 di-deploy. | O22: Diperbaiki – uji ulang
A23: TC-022 | B23: Reservasi | C23: Check out dan invoice | D23: Tamu sudah check in | E23: Room Reservation > Check out > proses pembayaran; buka Customer Invoice | F23: Bayar tunai penuh | G23: Invoice terbit; sisa tagihan 0; kamar kembali tersedia | H23: data tidak muncul di tabel | I23: Gagal | J23: https://drive.google.com/file/d/1S8Y9PQ_bEK_qa2Ip9yD85X_-BRb8d4rp/view?usp=drive_link | M23: melati@egzy.test | N23: Terblokir penyebab yang sama dengan TC-020. Catatan perhitungan: harga kamar = per malam termasuk PBJT; tagihan = harga per malam x jumlah malam. Berlaku di server setelah rilis 9 Okt 2026 di-deploy. | O23: Diperbaiki – uji ulang
A24: TC-023 | B24: Reservasi | C24: Booking ganda kamar yang sama | D24: Kamar 101 sudah dibooking | E24: Buat booking kedua untuk kamar dan tanggal yang sama | F24: Deluxe 101; tanggal sama | G24: Sistem menolak atau kamar tidak bisa dipilih | H24: setelah isi form kemudian disimpan data tidak muncul di tabel | I24: Gagal | M24: melati@egzy.test | N24: Diverifikasi di salinan lokal: booking kedua kamar & tanggal yang sama ditolak "Room No ... is not available". Berlaku di server setelah rilis 9 Okt 2026 di-deploy. | O24: Diperbaiki – uji ulang
A25: TC-024 | B25: Reservasi | C25: Wake up call | D25: Tamu sudah check in | E25: Customer > Wake up call list > tambah | F25: Kamar 101; 05:00 | G25: Data tampil di Wake up call list | H25: Sudah sesuai | I25: Lulus | M25: melati@egzy.test | O25: Tidak ada perubahan
A26: TC-025 | B26: Restoran | C26: Tambah kategori dan makanan | D26: - | E26: Manage category > Add category; Manage food > Add food | F26: Kategori: Makanan Utama; Food: Nasi Goreng; VAT: 10% | G26: Makanan tampil di Food list dan di POS | H26: gambar makanan tidak muncul | I26: Gagal | J26: https://drive.google.com/file/d/1jiV3j2Ihq1rhHz7l3GeJb_LLxo9egCi-/view?usp=sharing | K26: 46304 | L26: Syarah | M26: bahari@egzy.test | N26: Ronde 2 (9 Okt): Gambar menu yang diunggah SEBELUM perbaikan izin folder tersimpan tanpa gambar: edit item & unggah ulang. Aplikasi kini menampilkan pesan bila upload gagal. Status per item & izin folder dapat dicek dengan pbjt_diagnosa.php. Berlaku setelah rilis berikutnya di-deploy (sertakan migrasi 011–012) dan cache Cloudflare di-purge. | O26: Diperbaiki – uji ulang
A27: TC-026 | B27: Restoran | C27: Tambah add-ons dan assign | D27: Makanan sudah ada | E27: Add-ons > Add add-ons; Add-ons assign list > Add-ons Assign | F27: Add-ons: Telur; Price: 5.000; ke Nasi Goreng | G27: Add-ons tampil saat memesan Nasi Goreng di POS | H27: Sesuai | I27: Lulus | K27: 46303 | L27: Syarah | M27: bahari@egzy.test | O27: Tidak ada perubahan
A28: TC-027 | B28: Restoran | C28: Tambah meja | D28: - | E28: Manage table > Table list > Add Floor > Add Table | F28: Lantai 1; Meja 1; Capacity: 4 | G28: Meja tampil di Table list | H28: Sesuai | I28: Lulus | K28: 46303 | L28: Syarah | M28: bahari@egzy.test | O28: Tidak ada perubahan
A29: TC-028 | B29: Restoran | C29: Start Cash Register | D29: Counter sudah ada | E29: Buka POS invoice > isi pop-up Start Cash Register | F29: Counter 1; saldo awal 500.000 | G29: Kasir terbuka; pop-up tidak muncul lagi di halaman lain | H29: Sesuai | I29: Lulus | K29: 46303 | L29: Syarah | M29: bahari@egzy.test | O29: Tidak ada perubahan
A30: TC-029 | B30: Restoran | C30: Buat order di POS | D30: Kasir terbuka; makanan dan meja ada | E30: POS invoice > pilih makanan, meja, waiter > Place Order | F30: Nasi Goreng x2; Meja 1 | G30: Order masuk ke Order list dan Pending order; total termasuk pajak benar | H30: nama waiter tidak muncul | I30: Gagal | J30: https://drive.google.com/file/d/18j3OG2Gt0ZtSzZ_oISonBGPSe7L3zS8H/view?usp=sharing | K30: 46304 | L30: Syarah | M30: bahari@egzy.test | N30: Ronde 2 (9 Okt): Penyebab: daftar waiter hanya menampilkan pegawai yang sudah tercatat HADIR (absen masuk) pada shift berjalan. Kini pegawai yang terjadwal di Duty Roster pada shift berjalan langsung muncul walau belum absen (kecuali cuti/absen); shift lintas tengah malam juga dikenali. Berlaku setelah rilis berikutnya di-deploy (sertakan migrasi 011–012) dan cache Cloudflare di-purge. | O30: Diperbaiki – uji ulang
A31: TC-030 | B31: Restoran | C31: Selesaikan dan bayar order | D31: Order pending ada | E31: Pending order > proses pembayaran | F31: Bayar tunai | G31: Order pindah ke Complete order; Counter dashboard terbarui | H31: Sesuai | I31: Lulus | K31: 46303 | L31: Syarah | M31: bahari@egzy.test | N31: POS kini menghitung PBJT dari engine PBJT: total = subtotal - diskon + service charge + PBJT 10% (harga menu belum termasuk PBJT). Periksa nilai total/struk. Berlaku di server setelah rilis 9 Okt 2026 di-deploy. | O31: Diperbaiki – uji ulang
A32: TC-031 | B32: Restoran | C32: Batalkan order | D32: Order pending ada | E32: Batalkan salah satu order | F32: Alasan: salah pesan | G32: Order pindah ke Cancel order; tidak masuk pendapatan | H32: Sesuai | I32: Lulus | K32: 46303 | L32: Syarah | M32: bahari@egzy.test | O32: Tidak ada perubahan
A33: TC-032 | B33: Restoran | C33: Day closing | D33: Ada transaksi hari ini | E33: Day Closing > Report > pilih tanggal, kasir, counter > Search | F33: Tanggal hari ini; Counter 1 | G33: Total sama dengan jumlah order selesai; Print Date sesuai jam setempat | H33: Sesuai | I33: Lulus | K33: 46303 | L33: Syarah | M33: bahari@egzy.test | N33: Penyebab selisih jam: laporan memaksa zona waktu Asia/Dhaka (UTC+6) dan format 12 jam. Kini memakai zona waktu tenant (WIB) dan format 24 jam; zona waktu WIB juga diterapkan untuk seluruh aplikasi. Berlaku di server setelah rilis 9 Okt 2026 di-deploy. | O33: Diperbaiki – uji ulang
A34: TC-033 | B34: Stok dan pembelian | C34: Tambah unit, kategori, produk, supplier | D34: - | E34: Unit and Products > Unit measurement list, Category list, Products list, Supplier list > tambah | F34: Unit: Kilogram; Produk: Beras; Supplier: CV Sumber Pangan | G34: Semua tampil dan bisa dipilih di form pembelian | H34: Sesuai | I34: Lulus | M34: bahari@egzy.test | O34: Tidak ada perubahan
A35: TC-034 | B35: Stok dan pembelian | C35: Tambah pembelian | D35: Produk dan supplier sudah ada | E35: Purchase Manage > Add purchase > isi > simpan | F35: Beras 50 kg @12.000 | G35: Tampil di Purchase item; Stock report bertambah 50; Purchase report 600.000 | H35: Sesuai | I35: Lulus | K35: 46304 | L35: Syarah | M35: bahari@egzy.test | O35: Tidak ada perubahan
A36: TC-035 | B36: Stok dan pembelian | C36: Retur pembelian | D36: Pembelian sudah ada | E36: Purchase Manage > Purchase return > pilih invoice > retur | F36: Beras 2 kg; Comments: basah | G36: Tampil di Return invoice; stok menjadi 45 | H36: Sesuai | I36: Lulus | K36: 46304 | L36: Syarah | M36: bahari@egzy.test | N36: Penyebab: pemilih tanggal retur "Invalid date" karena tahun buku kosong, menutupi form. Diperbaiki bersama TC-020 (migrasi 006 + datepicker). Berlaku di server setelah rilis 9 Okt 2026 di-deploy. | O36: Diperbaiki – uji ulang
A37: TC-036 | B37: Stok dan pembelian | C37: Produk rusak | D37: Stok tersedia | E37: Unit and Products > Destroyed list > Add Product | G37: Tampil di Destroyed list; stok berkurang 2 | H37: Destroy list tampil tapi stock tidak berkurang 2 | I37: Gagal | J37: https://drive.google.com/file/d/113JBeBqUuAgHNqXsYGk4hcb7CuCUrZAZ/view?usp=sharing | K37: 46304 | L37: Syarah | M37: bahari@egzy.test | N37: Ronde 2 (9 Okt): Penyebab: laporan stok hanya menjumlahkan qty pembelian, sehingga retur & produk rusak tak pernah mengurangi angka. Laporan kini menampilkan Dibeli, Diretur, Rusak, Terpakai, Stok saat ini (50 - 2 = 48) dan nilai pembelian yang benar. Berlaku setelah rilis berikutnya di-deploy (sertakan migrasi 011–012) dan cache Cloudflare di-purge. | O37: Diperbaiki – uji ulang
A38: TC-037 | B38: House Keeping | C38: Tugaskan dan selesaikan pembersihan | D38: Pegawai dan kamar sudah ada | E38: Assign room cleaning > pilih house keeper, kamar > Add; lalu Room cleaning > ubah status | F38: House keeper: Budi; kamar 101 | G38: Tugas tampil di Room cleaning; Reports menunjukkan Complete 1 | H38: DATA MASIH BELUM MUNCUL PADAHAL SUDAH DI ASSIGN | I38: Gagal | J38: https://drive.google.com/file/d/1m2ktRpR-E2n_0d7o-tFI40V4MWkvKqw4/view?usp=drive_link | K38: 46304 | L38: FERI | M38: melati@egzy.test | N38: Ronde 2 (9 Okt): Penyebab sama dengan TC-029: house keeper harus sudah absen masuk. Kini cukup terjadwal pada shift berjalan. Berlaku setelah rilis berikutnya di-deploy (sertakan migrasi 011–012) dan cache Cloudflare di-purge. | O38: Diperbaiki – uji ulang
A39: TC-038 | B39: House Keeping | C39: Buka menu Records | D39: - | E39: House Keeping > Records | F39: - | G39: Halaman terbuka tanpa error | H39: Sesuai | I39: Lulus | K39: 46304 | L39: Syarah | M39: melati@egzy.test | N39: Penyebab: collation kolom database bercampur sehingga JOIN error 500. Semua tabel diseragamkan (migrasi 005). Diverifikasi di salinan lokal: halaman terbuka. Berlaku di server setelah rilis 9 Okt 2026 di-deploy. | O39: Diperbaiki – uji ulang
A40: TC-039 | B40: House Keeping | C40: Laundry | D40: Produk laundry sudah ada | E40: Laundry > Item cost > Manage Item; Laundry list; Payment | F40: Item: Sprei; Cost: 10.000 | G40: Biaya tampil; Laundry Payment menunjukkan total, dibayar, sisa yang benar | H40: Produk sudah ada tinggal "Task Name" dimana untuk inputnya/pilihnya? | I40: Gagal | J40: https://drive.google.com/file/d/1OtmhC8WKdSVVj2dcL2w0kZEzQEiXP6N0/view?usp=drive_link | K40: 46304 | L40: FERI | M40: melati@egzy.test | N40: Ronde 2 (9 Okt): Task Name diambil dari House Keeping > Checklist dengan Type = Laundry (mis. "Cuci & setrika"); form Item cost kini menampilkan petunjuk + tautan. Berlaku setelah rilis berikutnya di-deploy (sertakan migrasi 011–012) dan cache Cloudflare di-purge. | O40: Diperbaiki – uji ulang
...

Sheet Rekonsiliasi WP
A1: ID | B1: Wajib pajak | C1: Peran dalam skenario | D1: Akun tenant | E1: Menu yang dicek | F1: Hasil yang diharapkan | G1: Hasil aktual | H1: Status | I1: Catatan | J1: Tanggal uji | K1: Penguji | L1: Akun login | M1: Tindak lanjut pengembang (9 Okt 2026) | N1: Status perbaikan
A2: RK-01 | B2: Melati | C2: Patuh | D2: melati@egzy.test | E2: Rekonsiliasi, Selisih/Gap, STPD, Status Kepatuhan | F2: QRIS sekitar 0,5-0,6 kali omzet; tagihan lunas; tidak ada temuan; status patuh | G2: sesuai | H2: Lulus | J2: 46244 | K2: Syarah | L2: bapenda@egzy.test | M2: Data demo di-seed ulang dengan perhitungan PBJT baru (kamar termasuk pajak, restoran ditambah PBJT); nilai tagihan berubah, rasio QRIS tetap. Uji ulang angka. Berlaku di server setelah rilis 9 Okt 2026 di-deploy. | N2: Diperbaiki – uji ulang
A3: RK-02 | B3: Sunda Asli | C3: Patuh | D3: tidak disebut di pesan | E3: Rekonsiliasi, Selisih/Gap, STPD, Status Kepatuhan | F3: QRIS sekitar 0,5-0,6 kali omzet; tagihan lunas; tidak ada temuan; status patuh | G3: sesuai | H3: Lulus | J3: 46244 | K3: Syarah | L3: bapenda@egzy.test | M3: Uji ulang angka setelah seed ulang (lihat RK-01). Berlaku di server setelah rilis 9 Okt 2026 di-deploy. | N3: Diperbaiki – uji ulang
A4: RK-03 | B4: Nirwana | C4: Patuh | D4: nirwana@egzy.test | E4: Rekonsiliasi, Selisih/Gap, STPD, Status Kepatuhan | F4: QRIS sekitar 0,5-0,6 kali omzet; tagihan lunas; tidak ada temuan; status patuh | G4: sesuai | H4: Lulus | J4: 46244 | K4: Syarah | L4: bapenda@egzy.test | M4: Uji ulang angka setelah seed ulang (lihat RK-01). Berlaku di server setelah rilis 9 Okt 2026 di-deploy. | N4: Diperbaiki – uji ulang
A5: RK-04 | B5: Serena | C5: Kurang lapor | D5: serena@egzy.test | E5: Rekonsiliasi, Selisih/Gap | F5: QRIS 1,14 lalu 1,32 kali omzet pada dua masa pajak; muncul temuan risiko tinggi | G5: sesuai | H5: Lulus | I5: Jatuh tempo setiap tanggal 10 setiap bulannya | J5: 46244 | K5: Syarah | L5: bapenda@egzy.test | M5: Jatuh tempo diubah ke tanggal 10 bulan berikutnya, sesuai catatan penguji. Berlaku di server setelah rilis 9 Okt 2026 di-deploy. | N5: Diperbaiki – uji ulang
A6: RK-05 | B6: Kenanga | C6: Dua outlet QRIS, satu tanpa tapping box | D6: tidak disebut di pesan | E6: Rekonsiliasi, Selisih/Gap | F6: Muncul temuan; outlet tanpa tapping box teridentifikasi | G6: tidak ada akun tenant | H6: Gagal | I6: tidak ada akun tenant | L6: bapenda@egzy.test | M6: Ronde 2 (9 Okt): Bukan bug: Guest House Kenanga, Cafe Kopi Senja, dan Warung Steak Jaya adalah WP tapping box (tanpa akun aplikasi). Uji lewat akun bapenda@egzy.test di menu Pengawasan PBJT (pilih masa September 2026). | N6: Tidak ada perubahan
A7: RK-06 | B7: Kopi Senja | C7: Selisih tipis dan outlet baru belum terdaftar | D7: tidak disebut di pesan | E7: Selisih/Gap, Review Pendaftaran | F7: Temuan tingkat sedang; MID QR-SNJ-02 tampil di antrean | G7: tidak ada akun tenant | H7: Gagal | I7: tidak ada akun tenant | L7: bapenda@egzy.test | M7: Ronde 2 (9 Okt): Bukan bug: Guest House Kenanga, Cafe Kopi Senja, dan Warung Steak Jaya adalah WP tapping box (tanpa akun aplikasi). Uji lewat akun bapenda@egzy.test di menu Pengawasan PBJT (pilih masa September 2026). | N7: Tidak ada perubahan
A8: RK-07 | B8: Steak Jaya | C8: Ada refund QRIS | D8: tidak disebut di pesan | E8: Rekonsiliasi, Status Kepatuhan | F8: Refund diperhitungkan; WP tetap berstatus patuh; tidak ada temuan | G8: tidak ada akun tenant | H8: Gagal | I8: tidak ada akun tenant | L8: bapenda@egzy.test | M8: Ronde 2 (9 Okt): Bukan bug: Guest House Kenanga, Cafe Kopi Senja, dan Warung Steak Jaya adalah WP tapping box (tanpa akun aplikasi). Uji lewat akun bapenda@egzy.test di menu Pengawasan PBJT (pilih masa September 2026). | N8: Tidak ada perubahan
A9: RK-08 | B9: Cempaka | C9: Telat bayar | D9: cempaka@egzy.test | E9: STPD, Realisasi Pembayaran | F9: VA masa Agustus berstatus kedaluwarsa; tagihan tercatat belum dibayar atau terlambat | G9: sesuai | H9: Lulus | I9: Penerbitan STPD harus dalam bentuk dokumen | J9: 46244 | K9: Syarah | L9: bapenda@egzy.test | M9: STPD kini berupa dokumen siap cetak: Bapenda > tabel tagihan > "Terbitkan STPD". Memuat identitas WP, masa, pokok, jatuh tempo, tanggal bayar/terbit, bulan terlambat, bunga, total. Bertanda DRAFT: parameter sanksi (1%/bulan, maks 24 bulan) BELUM DIVERIFIKASI terhadap Perda PDRD / PP 35/2023. Berlaku di server setelah rilis 9 Okt 2026 di-deploy. | N9: Diperbaiki – uji ulang
A10: RK-09 | B10: Villa Asri | C10: Tenant baru | D10: villa@egzy.test | E10: MPOS tenant Villa; SPTPD, STPD | F10: Kamar sudah tersedia di MPOS; belum ada tagihan di dashboard; tidak ditandai menunggak | G10: sesuai | H10: Lulus | J10: 46244 | K10: Syarah | L10: bapenda@egzy.test dan villa@egzy.test | N10: Tidak ada perubahan
A11: RK-10 | B11: Bahari | C11: Restoran dengan POS | D11: bahari@egzy.test | E11: MPOS tenant Bahari > Order List; Estimasi PBJT | F11: Sekitar 640 order kasir; omzet di dashboard sama dengan total order selesai | G11: dashboard yang muncul adalah dashboad hotel | H11: Lulus | I11: https://drive.google.com/file/d/1ly0k_gryFdaLOKcmUh6aHOlvdFxk4BAH/view?usp=sharing | J11: 46244 | K11: Syarah | L11: bapenda@egzy.test dan bahari@egzy.test | M11: Tenant restoran kini mendapat dashboard restoran: order hari ini, omzet order selesai, order berjalan/batal, PBJT bulan ini, tren bulanan, order terbaru. Berlaku di server setelah rilis 9 Okt 2026 di-deploy. | N11: Diperbaiki – uji ulang
A12: RK-11 | B12: Nirwana | C12: Tamu bayar lewat VA BNI | D12: nirwana@egzy.test | E12: MPOS tenant Nirwana > Booking list; Realisasi Pembayaran | F12: Sekitar 40% booking dibayar lewat VA; pembayaran VA tercatat | G12: data booking tidak muncul | H12: Gagal | I12: https://drive.google.com/file/d/1Jd72AYYF7tW1YddMKLwTTRKaJzAlhGII/view?usp=drive_link | J12: 46244 | K12: FERI | L12: bapenda@egzy.test dan nirwana@egzy.test | M12: Booking yang dibayar via VA umumnya sudah check-out, dan dulu tidak ada daftar untuk booking selesai. Booking list kini punya filter status; pilih "Checkout" atau "Semua". Pembuatan booking juga diperbaiki (TC-020). Berlaku di server setelah rilis 9 Okt 2026 di-deploy. | N12: Diperbaiki – uji ulang
A14: Sumber: pesan pengembang tentang 10 WP contoh. Nirwana punya dua baris karena memegang dua peran.
A15: Kolom Menu yang dicek adalah perkiraan dari nama menu di dashboard Bapenda; sesuaikan bila letaknya berbeda.
A16: Rasio QRIS terhadap omzet di atas 1 berarti penerimaan QRIS melebihi omzet yang dilaporkan.

Sheet Temuan Awal
A1: No | B1: Lokasi | C1: Temuan dari screenshot | D1: Tingkat | E1: Status perbaikan
A2: 1 | B2: Role bapenda@egzy.test | C2: Petugas Bapenda masih melihat seluruh menu hotel (Room Reservation, Restaurant, Payroll, dan lainnya). Layak diuji: data siapa yang tampil di sana, dan apakah petugas Bapenda bisa mengubah data operasional tenant. | D2: Tinggi | E2: Diperbaiki: menu operasional disembunyikan untuk Bapenda dan aksesnya ditolak server (termasuk lewat alamat langsung); beranda Bapenda = Pengawasan PBJT. Data yang tampil dulu adalah data database pengawasan sendiri, bukan data WP.
A3: 2 | B3: Role hotel dan resto | C3: Dashboard hotel dan resto | D3: Tinggi | E3: Ronde 2 (9 Okt): Diperbaiki: hotel yang juga punya restoran (mis. Melati, Nirwana) kini melihat ringkasan restoran (order hari ini, omzet selesai, order berjalan, PBJT restoran bulan ini) di dashboard hotel; tenant restoran memakai dashboard restoran.
A4: 3 | B4: Dashboard Restoran | C4: Saat ini dashboard maish menampilkan dashboard hotel | D4: Tinggi | E4: Diperbaiki: tenant restoran mendapat dashboard restoran (lihat RK-10).
A5: 4 | B5: Records (House Keeping) | C5: HTTP Error 500 saat menu dibuka | D5: Tinggi | E5: Diperbaiki: penyeragaman collation database (migrasi 005). Halaman Laundry punya penyebab yang sama.
A6: 5 | B6: Customer type list | C6: Hotel, Online, dan Walk In Customer masing-masing muncul dua kali | D6: Sedang | E6: Diperbaiki: duplikat dihapus (migrasi 008).
A7: 6 | B7: Day Closing report | C7: Print Date 12:55:55 padahal jam aplikasi 13:56:08; selisih sekitar satu jam | D7: Sedang | E7: Diperbaiki: zona waktu Asia/Dhaka yang dipaksakan dihapus; format 24 jam; seluruh aplikasi kini memakai WIB (dulu UTC).
A8: 7 | B8: Format tanggal | C8: Attendance dashboard 10/07/2026, Day Closing 07/10/2026 | D8: Sedang | E8: Diperbaiki: Attendance dashboard memakai DD/MM/YYYY.
A9: 8 | B9: Restaurant table setup | C9: Halaman kosong (mungkin karena belum ada meja) | D9: Perlu dicek | E9: Benar karena belum ada meja; kini tampil pesan "Belum ada meja". Ikon meja default yang hilang juga diperbaiki.
A10: 9 | B10: Room QR list | C10: Halaman kosong (mungkin karena belum ada kamar) | D10: Perlu dicek | E10: Bukan karena belum ada kamar: QR memakai layanan Google yang sudah mati. Diperbaiki (lihat TC-018).
A11: 10 | B11: Sound setting | C11: Ikon Notify Sound rusak | D11: Rendah | E11: Diperbaiki: file suara ditampilkan sebagai gambar; kini pemutar audio. File bawaan yang hilang diganti bunyi yang tersedia.
A12: 11 | B12: Car Parking - Setting list | C12: Teks tombol Submit dan Reset terpotong dua baris | D12: Rendah | E12: Diperbaiki (lihat TC-041).
A13: 12 | B13: Add user (Settings) | C13: Email dan password terisi otomatis oleh browser di form tambah user | D13: Rendah | E13: Diperbaiki (lihat TC-048).
... A15: 14 | B15: QRIS 60 % dari total omzet | C15: Pertanyaan untuk pengembang: Di mana angka 0,6 ditetapkan, dan bisakah diubah per jenis usaha atau per WP? Apa dasar angka itu: data nyata atau perkiraan untuk demo? Apakah "QRIS agregat" mencakup transaksi kartu (EDC)? | D15: Rendah | E15: Dijawab: 0,6 = parameter porsi non-tunai bawaan engine, satu nilai untuk semua WP (belum per jenis usaha/WP). Nilai demo, bukan data nyata; perlu disepakati dengan Bapenda.
A16: 15 | C16: Apakah angkanya sudah dikurangi refund dan biaya bank (MDR), dan apakah transaksi kartu lewat mesin EDC ikut dijumlahkan, karena subjudul halaman menyebut "QRIS/EDC" sedangkan nama kolomnya hanya "QRIS" | D16: Rendah | E16: Dijawab: refund QRIS ikut dihitung (nilai negatif). Nilai settlement dipakai apa adanya dari bank (belum disesuaikan MDR). Data demo hanya berisi QRIS; transaksi kartu EDC belum dipisahkan dan perlu dikonfirmasi dari format file settlement bank.

Sheet Perbaikan desain
A1: No | B1: Menu | C1: Gambar | H1: Saran Perbaikan | I1: Status perbaikan (9 Okt 2026)
A2: 1 | B2: Menu POS restoran | H2: Warna teks diganti warna hitam supaya mudha dibaca | I2: Diperbaiki: teks tab POS (New/On Going/Online/Today Order) kini hitam. Berlaku di server setelah rilis 9 Okt 2026 di-deploy.
H3: Belum berwarna hitam | I3: Ronde 2 (9 Okt): Kode sudah benar sejak rilis lalu (diverifikasi di browser: teks tab hitam). Yang tampil di server adalah CSS lama dari cache Cloudflare/browser karena versi file tetap "?v=1". Kini semua CSS/JS diberi versi otomatis per perubahan; purge cache Cloudflare sekali setelah deploy.
A6: 2 | B6: Add employee | H6: Hapus | I6: Ronde 2 (9 Okt): Diperbaiki: field Ethnic Group dan EEO Class dihapus dari form tambah & ubah pegawai (nilai lama tetap tersimpan).
A14: 3 | B14: Tambah Booking Type | H14: Walk-in Tamu datang langsung ke resepsionis Telepon / WhatsApp Pesan lewat telepon atau chat ke hotel Website Hotel Pesan lewat website hotel sendiri OTA Online travel agent seperti Traveloka, Tiket.com Korporat Kontrak dengan perusahaan atau instansi Travel Agent Biro perjalanan konvensional Grup / Event Rombongan, rapat, pernikahan | I14: Ronde 2 (9 Okt): Diperbaiki: tujuh booking type bawaan ditambahkan bila belum ada (Walk-in, Telepon / WhatsApp, Website Hotel, OTA (Traveloka, Tiket.com, dll.), Korporat, Travel Agent, Grup / Event) — migrasi 012. Tipe buatan hotel tidak diubah.
A20: 4 | B20: Menu Side bar
H21: Ganti total amount menjadi rupiah | I21: Ronde 2 (9 Okt): Diperbaiki: angka dashboard memakai format Indonesia; Total Amount kini "Rp 234,8 jt" (bukan "240.3m"), hitungan memakai titik ribuan.
A24: 5 | B24: Menu Sidebar | H24: Belum Responsive | I24: Ronde 2 (9 Okt): Diperbaiki: saat sidebar diciutkan, teks menu terpotong satu huruf, logo terpotong, avatar lonjong — kini hanya ikon + logo "E" + avatar bulat (teks muncul saat di-hover). Di ponsel sidebar yang dibuka tidak tertutup navbar.
A50: 6 | B50: Semua Menu | H50: Perbaikan layout dan penyesuaian baik form field button, reponsive setiap element. yang masih mepet tumpang tindih dllnya🙏🏻 | I50: Ronde 2 (9 Okt): Sebagian: baris tabel kini ringkas (tombol aksi tidak menumpuk), sidebar mode mini & ponsel dirapikan. Mohon sebutkan halaman spesifik yang masih mepet/tumpang tindih (screenshot) agar bisa diperbaiki satu per satu.
A51: 7 | B51: Semua Halaman untuk branding | H51: mungkin nanti bisa di ganti warna brandingnya ke biru penyesuaian dengan logo mentawai warna biru | I51: Menunggu keputusan: perlu file logo Mentawai/warna biru resmi (kode warna). Tema memakai variabel warna terpusat sehingga penggantian warna branding cukup di satu tempat.
H52: style dibuat lebih konsisten baik dari typography warna dan lainnya
A54: 8 | B54: Semua Menu | H54: Flow inputan kemudian penempatan masih membingungkan, masih harus dipelajari lebih mendalam bantu untuk tampilan lebih user friendly apakah bisa dibantu untuk di tambahkan informasi seperti yang sudah dibuat "(halaman kini memberi petunjuk)" | I54: Ronde 2 (9 Okt): Sebagian: petunjuk ditambahkan di halaman yang dilaporkan (Laundry, Item cost, Assign room cleaning, Table setup, Tax Management). Mohon daftar halaman/alur lain yang membingungkan untuk ditambahkan petunjuk serupa.
